Workbook
Name NativeTimeline_Order_Date: #N/A
Name Slicer_Region: #N/A

Sheet Summary
A1: SUMMARY
A2: Section1: Data Entry & Data Cleaning
A3: Customer Dim Sheet
A4: Name Colum trim and Proper done
A5: Customer ID had 4 inconsistent name as C-. Used find and Replace to correct it
A6: No Duplicate Values found in Customer ID
A7: Missing Values in Loyalty level were corrected using highest number of loyalty levels observed in that state
A9: Product Dim Sheet
A10: No need for proper or trimming
A11: No Duplicates found
A12: 3 Missing values in stock changed to 0 as no data found
A13: 6 Missing Values in Cost are corrected based on average sub categories and similar products
... A26: Sales Dashboard

Sheet Sales Dashboard
A1: Sales Dashboard

Sheet Customer_Dim (2)
A1: Customer_ID | B1: Name | C1: Proper name | D1: Trim | E1: Age | F1: Gender | G1: City | H1: State | I1: Country | J1: Loyalty_Level
A2: CUST1000 | B2: sheena bonilla | C2: =PROPER(Table26[[#This Row],[Name]]) -> Sheena Bonilla | D2: =TRIM(Table26[[#This Row],[Proper name]]) -> Sheena Bonilla | E2: 55 | F2: Male | G2: Donaldton | H2: North Carolina | I2: USA | J2: Platinum
A3: CUST1001 | B3: Eugene Nelson | C3: =PROPER(Table26[[#This Row],[Name]]) -> Eugene Nelson | D3: =TRIM(Table26[[#This Row],[Proper name]]) -> Eugene Nelson | E3: 26 | F3: Female | G3: Phillipsmouth | H3: North Dakota | I3: USA | J3: Platinum
A4: CUST1002 | B4: dr. Benjamin Price | C4: =PROPER(Table26[[#This Row],[Name]]) -> Dr. Benjamin Price | D4: =TRIM(Table26[[#This Row],[Proper name]]) -> Dr. Benjamin Price | E4: 29 | F4: Female | G4: Kylebury | H4: Alabama | I4: USA | J4: Platinum
A5: CUST1003 | B5: jeremy harris | C5: =PROPER(Table26[[#This Row],[Name]]) -> Jeremy Harris | D5: =TRIM(Table26[[#This Row],[Proper name]]) -> Jeremy Harris | E5: 59 | F5: Female | G5: Thomastown | H5: Ohio | I5: USA | J5: Bronze
A6: CUST1004 | B6: Caroline Collins | C6: =PROPER(Table26[[#This Row],[Name]]) -> Caroline Collins | D6: =TRIM(Table26[[#This Row],[Proper name]]) -> Caroline Collins | E6: 64 | F6: Female | G6: Nicholasshire | H6: California | I6: USA | J6: Silver
A7: CUST1005 | B7: Christine Vaughn | C7: =PROPER(Table26[[#This Row],[Name]]) -> Christine Vaughn | D7: =TRIM(Table26[[#This Row],[Proper name]]) -> Christine Vaughn | E7: 24 | F7: Male | G7: East Amandamouth | H7: Oregon | I7: USA | J7: Bronze
A8: CUST1006 | B8: Amber Jackson | C8: =PROPER(Table26[[#This Row],[Name]]) -> Amber Jackson | D8: =TRIM(Table26[[#This Row],[Proper name]]) -> Amber Jackson | E8: 29 | F8: Female | G8: Deborahborough | H8: South Dakota | I8: USA | J8: Platinum
A9: CUST1007 | B9: Daniel Boyd | C9: =PROPER(Table26[[#This Row],[Name]]) -> Daniel Boyd | D9: =TRIM(Table26[[#This Row],[Proper name]]) -> Daniel Boyd | E9: 29 | F9: Female | G9: West Pamelafurt | H9: West Virginia | I9: USA | J9: Bronze
A10: CUST1008 | B10: Melissa Howard | C10: =PROPER(Table26[[#This Row],[Name]]) -> Melissa Howard | D10: =TRIM(Table26[[#This Row],[Proper name]]) -> Melissa Howard | E10: 53 | F10: Female | G10: Maynardton | H10: New Hampshire | I10: USA | J10: Gold
A11: CUST1009 | B11: Ms. Maria Leach | C11: =PROPER(Table26[[#This Row],[Name]]) -> Ms. Maria Leach | D11: =TRIM(Table26[[#This Row],[Proper name]]) -> Ms. Maria Leach | E11: 64 | F11: Male | G11: Melissashire | H11: Pennsylvania | I11: USA | J11: Platinum
A12: CUST1010 | B12: Dominic Page | C12: =PROPER(Table26[[#This Row],[Name]]) -> Dominic Page | D12: =TRIM(Table26[[#This Row],[Proper name]]) -> Dominic Page | E12: 53 | F12: Male | G12: Port Michaelburgh | H12: Pennsylvania | I12: USA | J12: Bronze
A13: CUST1011 | B13: Brian Lopez | C13: =PROPER(Table26[[#This Row],[Name]]) -> Brian Lopez | D13: =TRIM(Table26[[#This Row],[Proper name]]) -> Brian Lopez | E13: 28 | F13: Female | G13: East Krista | H13: New York | I13: USA | J13: Gold
... A501: CUST1499 | B501: Philip Pennington | C501: =PROPER(Table26[[#This Row],[Name]]) -> Philip Pennington | D501: =TRIM(Table26[[#This Row],[Proper name]]) -> Philip Pennington | E501: 27 | F501: Female | G501: East Valerieview | H501: Oregon | I501: USA | J501: Platinum

Sheet Customer_Dim
A1: Customer_ID | B1: Name | C1: Age | D1: Gender | E1: City | F1: State | G1: Country | H1: Loyalty_Level
A2: CUST1000 | B2: Sheena Bonilla | C2: 55 | D2: Male | E2: Donaldton | F2: North Carolina | G2: USA | H2: Platinum
A3: CUST1001 | B3: Eugene Nelson | C3: 26 | D3: Female | E3: Phillipsmouth | F3: North Dakota | G3: USA | H3: Platinum
A4: CUST1002 | B4: Dr. Benjamin Price | C4: 29 | D4: Female | E4: Kylebury | F4: Alabama | G4: USA | H4: Platinum
A5: CUST1003 | B5: Jeremy Harris | C5: 59 | D5: Female | E5: Thomastown | F5: Ohio | G5: USA | H5: Bronze
A6: CUST1004 | B6: Caroline Collins | C6: 64 | D6: Female | E6: Nicholasshire | F6: California | G6: USA | H6: Silver
A7: CUST1005 | B7: Christine Vaughn | C7: 24 | D7: Male | E7: East Amandamouth | F7: Oregon | G7: USA | H7: Bronze
A8: CUST1006 | B8: Amber Jackson | C8: 29 | D8: Female | E8: Deborahborough | F8: South Dakota | G8: USA | H8: Platinum
A9: CUST1007 | B9: Daniel Boyd | C9: 29 | D9: Female | E9: West Pamelafurt | F9: West Virginia | G9: USA | H9: Bronze
A10: CUST1008 | B10: Melissa Howard | C10: 53 | D10: Female | E10: Maynardton | F10: New Hampshire | G10: USA | H10: Gold
A11: CUST1009 | B11: Ms. Maria Leach | C11: 64 | D11: Male | E11: Melissashire | F11: Pennsylvania | G11: USA | H11: Platinum
A12: CUST1010 | B12: Dominic Page | C12: 53 | D12: Male | E12: Port Michaelburgh | F12: Pennsylvania | G12: USA | H12: Bronze
A13: CUST1011 | B13: Brian Lopez | C13: 28 | D13: Female | E13: East Krista | F13: New York | G13: USA | H13: Gold
... A501: CUST1499 | B501: Philip Pennington | C501: 27 | D501: Female | E501: East Valerieview | F501: Oregon | G501: USA | H501: Platinum

Sheet Product_Dim
A1: Product_ID | B1: Product_Name | C1: Category | D1: Sub_Category | E1: Brand | F1: Cost | G1: Stock
A2: PROD0 | B2: Brother Laser Printer | C2: Electronics | D2: Computer | E2: Hunt Inc | F2: 112.42 | G2: 416
A3: PROD1 | B3: Men's Graphic T-Shirt | C3: Clothing | D3: Tops | E3: Terry-Moore | F3: 342.56 | G3: 181
A4: PROD2 | B4: Women's Casual Hoodie | C4: Clothing | D4: Outerwear | E4: Sims Inc | F4: 167.34 | G4: 352
A5: PROD3 | B5: Men's Running Jacket | C5: Clothing | D5: Outerwear | E5: Pineda Ltd | F5: 364.67 | G5: 452
A6: PROD4 | B6: Women's Yoga Pants | C6: Clothing | D6: Bottoms | E6: Gonzales-Davis | F6: 306.46 | G6: 487
A7: PROD5 | B7: Men's Leather Belt | C7: Clothing | D7: Accessories | E7: Baldwin, Garza and Gonzalez | F7: 261 | G7: 59
A8: PROD6 | B8: Herbal Face Moisturizer | C8: Beauty | D8: Skincare | E8: Davidson PLC | F8: 312.8 | G8: 350
A9: PROD7 | B9: LED Table Lamp | C9: Home | D9: Lighting | E9: Harrell LLC | F9: 218.86 | G9: 170
A10: PROD8 | B10: Wireless Bluetooth Earbuds | C10: Electronics | D10: Audio | E10: Perez-Johnston | F10: 439.07 | G10: 142
A11: PROD9 | B11: Adjustable Dumbbell Set | C11: Sports | D11: Fitness | E11: Hill PLC | F11: 495.72 | G11: 323
A12: PROD10 | B12: Ceramic Kitchen Bowl Set | C12: Home | D12: Kitchen | E12: Hamilton Group | F12: 298.86 | G12: 308
A13: PROD11 | B13: HD Smart TV Stick | C13: Electronics | D13: Accessories | E13: Gibson, Hobbs and Weaver | F13: 449.4 | G13: 0
... A101: PROD99 | B101: Stainless Steel Cookware Set | C101: Home | D101: Kitchen | E101: Campbell Ltd | F101: 201.41 | G101: 146

Sheet Store_Dim
A1: Store_ID | B1: Store_Name | C1: Region | D1: City | E1: Store_Type
A2: STORE0 | B2: Rivera-Warner | C2: East | D2: Washingtonfurt | E2: Flagship
A3: STORE1 | B3: Martinez, Adkins and Johnson | C3: North | D3: Danielmouth | E3: Flagship
A4: STORE2 | B4: Black-Horn | C4: South | D4: North Nancyview | E4: Outlet
A5: STORE3 | B5: Johnson-Wright | C5: North | D5: Hoodberg | E5: Outlet
A6: STORE4 | B6: Alexander Group | C6: South | D6: Port Sharon | E6: Online
A7: STORE5 | B7: Gray Ltd | C7: North | D7: New Michaelchester | E7: Outlet
A8: STORE6 | B8: Benson-Elliott | C8: East | D8: Port Josephberg | E8: Online
A9: STORE7 | B9: Martinez-Mullins | C9: South | D9: Williamsfurt | E9: Online
A10: STORE8 | B10: Bean, Jones and Park | C10: West | D10: Thompsonborough | E10: Online
A11: STORE9 | B11: Moore, Padilla and Butler | C11: South | D11: East Johnstad | E11: Flagship
A12: STORE10 | B12: Hill, Wagner and Ballard | C12: East | D12: East Davidville | E12: Online
... A21: STORE19 | B21: Mann-Austin | C21: East | D21: Vasquezborough | E21: Online

Sheet Sales_Fact
A1: Sales_ID | B1: Order_Date | C1: Customer_ID | D1: Product_ID | E1: Store_ID | F1: Quantity | G1: Unit_Price | H1: Discount | I1: Payment_Type | J1: Total_Amount
A2: SALE0 | B2: 45480 | C2: CUST1409 | D2: PROD97 | E2: STORE3 | F2: 1 | G2: 218.04 | H2: 0.09 | I2: Credit Card | J2: 198.4164
A3: SALE1 | B3: 45285 | C3: CUST1467 | D3: PROD74 | E3: STORE17 | F3: 3 | G3: 104.47 | H3: 0.27 | I3: PayPal | J3: 228.7893
A4: SALE2 | B4: 45446 | C4: CUST1056 | D4: PROD49 | E4: STORE8 | F4: 4 | G4: 914.05 | H4: 0.25 | I4: Credit Card | J4: 2742.15
A5: SALE3 | B5: 45259 | C5: CUST1346 | D5: PROD76 | E5: STORE8 | F5: 1 | G5: 921.51 | H5: 0.16 | I5: COD | J5: 774.0684
A6: SALE4 | B6: 45297 | C6: CUST1493 | D6: PROD59 | E6: STORE5 | F6: 3 | G6: 745.3 | H6: 0.18 | I6: Credit Card | J6: 1833.438
A7: SALE5 | B7: 45499 | C7: CUST1116 | D7: PROD15 | E7: STORE7 | F7: 3 | G7: 147.01 | H7: 0.19 | I7: COD | J7: 357.2343
A8: SALE6 | B8: 45850 | C8: CUST1016 | D8: PROD56 | E8: STORE4 | F8: 2 | G8: 785.31 | H8: 0.15 | I8: PayPal | J8: 1335.027
A9: SALE7 | B9: 45248 | C9: CUST1152 | D9: PROD70 | E9: STORE8 | F9: 4 | G9: 342.39 | H9: 0.23 | I9: PayPal | J9: 1054.5612
A10: SALE8 | B10: 45781 | C10: CUST1187 | D10: PROD99 | E10: STORE5 | F10: 3 | G10: 448.25 | H10: 0.07 | I10: PayPal | J10: 1250.6175 | L10: =Table1[[#This Row],[Unit_Price]]*(1-Table1[[#This Row],[Discount]]) -> 416.8725 | M10: =Table1[[#This Row],[Total_Amount]]/L10 -> 3
A11: SALE9 | B11: 45869 | C11: CUST1464 | D11: PROD33 | E11: STORE0 | F11: 2 | G11: 873.17 | H11: 0.23 | I11: PayPal | J11: 1344.6818 | L11: =Table1[[#This Row],[Unit_Price]]*(1-Table1[[#This Row],[Discount]]) -> 672.3409 | M11: =Table1[[#This Row],[Total_Amount]]/L11 -> 2
A12: SALE10 | B12: 45335 | C12: CUST1065 | D12: PROD24 | E12: STORE14 | F12: 1 | G12: 278.63 | H12: 0.07 | I12: Credit Card | J12: 259.1259 | L12: =Table1[[#This Row],[Unit_Price]]*(1-Table1[[#This Row],[Discount]]) -> 259.1259 | M12: =Table1[[#This Row],[Total_Amount]]/L12 -> 1
A13: SALE11 | B13: 45801 | C13: CUST1320 | D13: PROD39 | E13: STORE1 | F13: 4 | G13: 286.92 | H13: 0.17 | I13: Credit Card | J13: 952.5744 | L13: =Table1[[#This Row],[Unit_Price]]*(1-Table1[[#This Row],[Discount]]) -> 238.1436 | M13: =Table1[[#This Row],[Total_Amount]]/L13 -> 4
A14: SALE12 | B14: 45528 | C14: CUST1237 | D14: PROD88 | E14: STORE4 | F14: 4 | G14: 644.58 | H14: 0.01 | I14: Credit Card | J14: 2552.5368 | L14: =Table1[[#This Row],[Unit_Price]]*(1-Table1[[#This Row],[Discount]]) -> 638.1342 | M14: =Table1[[#This Row],[Total_Amount]]/L14 -> 4
A15: SALE13 | B15: 45875 | C15: CUST1443 | D15: PROD34 | E15: STORE16 | F15: 2 | G15: 316.9 | H15: 0.3 | I15: PayPal | J15: 443.66 | L15: =Table1[[#This Row],[Unit_Price]]*(1-Table1[[#This Row],[Discount]]) -> 221.83 | M15: =Table1[[#This Row],[Total_Amount]]/L15 -> 2
A16: SALE14 | B16: 45829 | C16: CUST1348 | D16: PROD24 | E16: STORE15 | F16: 4 | G16: 403.47 | H16: 0.29 | I16: PayPal | J16: 1145.8548 | L16: =Table1[[#This Row],[Unit_Price]]*(1-Table1[[#This Row],[Discount]]) -> 286.4637 | M16: =Table1[[#This Row],[Total_Amount]]/L16 -> 4
A17: SALE15 | B17: 45636 | C17: CUST1435 | D17: PROD36 | E17: STORE9 | F17: 3 | G17: 871.34 | H17: 0.04 | I17: COD | J17: 2509.4592 | L17: =Table1[[#This Row],[Unit_Price]]*(1-Table1[[#This Row],[Discount]]) -> 836.4864 | M17: =Table1[[#This Row],[Total_Amount]]/L17 -> 3
A18: SALE16 | B18: 45913 | C18: CUST1276 | D18: PROD65 | E18: STORE19 | F18: 2 | G18: 451.98 | H18: 0.25 | I18: Credit Card | J18: 677.97 | L18: =Table1[[#This Row],[Unit_Price]]*(1-Table1[[#This Row],[Discount]]) -> 338.985 | M18: =Table1[[#This Row],[Total_Amount]]/L18 -> 2
A19: SALE17 | B19: 45637 | C19: CUST1079 | D19: PROD27 | E19: STORE4 | F19: 2 | G19: 502.69 | H19: 0.23 | I19: Credit Card | J19: 774.1426 | L19: =Table1[[#This Row],[Unit_Price]]*(1-Table1[[#This Row],[Discount]]) -> 387.0713 | M19: =Table1[[#This Row],[Total_Amount]]/L19 -> 2
A20: SALE18 | B20: 45517 | C20: CUST1094 | D20: PROD39 | E20: STORE4 | F20: 2 | G20: 559.23 | H20: 0.25 | I20: COD | J20: 838.845 | L20: =Table1[[#This Row],[Unit_Price]]*(1-Table1[[#This Row],[Discount]]) -> 419.4225 | M20: =Table1[[#This Row],[Total_Amount]]/L20 -> 2
A21: SALE19 | B21: 45369 | C21: CUST1239 | D21: PROD60 | E21: STORE13 | F21: 4 | G21: 464.18 | H21: 0.04 | I21: COD | J21: 1782.4512 | L21: =Table1[[#This Row],[Unit_Price]]*(1-Table1[[#This Row],[Discount]]) -> 445.6128 | M21: =Table1[[#This Row],[Total_Amount]]/L21 -> 4
... A27: SALE25 | B27: 45552 | C27: CUST1381 | D27: PROD5 | E27: STORE3 | F27: 4 | G27: 852.71 | H27: 0.14 | I27: PayPal | J27: 2933.3224 | L27: =Table1[[#This Row],[Unit_Price]]*(1-Table1[[#This Row],[Discount]]) -> 733.3306 | M27: =Table1[[#This Row],[Total_Amount]]/L27 -> 4
A28: SALE26 | B28: 45294 | C28: CUST1213 | D28: PROD98 | E28: STORE8 | F28: 4 | G28: 156.16 | H28: =1-(Table1[[#This Row],[Total_Amount]]/(Table1[[#This Row],[Unit_Price]]*Table1[[#This Row],[Quantity]])) -> 0.04 | I28: Credit Card | J28: 599.6544 | L28: =Table1[[#This Row],[Unit_Price]]*(1-Table1[[#This Row],[Discount]]) -> 149.9136 | M28: =Table1[[#This Row],[Total_Amount]]/L28 -> 4
A29: SALE27 | B29: 45710 | C29: CUST1200 | D29: PROD77 | E29: STORE8 | F29: 3 | G29: 815.49 | H29: 0.17 | I29: Credit Card | J29: 2030.5701 | L29: =Table1[[#This Row],[Unit_Price]]*(1-Table1[[#This Row],[Discount]]) -> 676.8567 | M29: =Table1[[#This Row],[Total_Amount]]/L29 -> 3
A30: SALE28 | B30: 45923 | C30: CUST1148 | D30: PROD13 | E30: STORE2 | F30: 2 | G30: 74.21 | H30: 0.11 | I30: PayPal | J30: 132.0938 | L30: =Table1[[#This Row],[Unit_Price]]*(1-Table1[[#This Row],[Discount]]) -> 66.0469 | M30: =Table1[[#This Row],[Total_Amount]]/L30 -> 2
A31: SALE29 | B31: 45302 | C31: CUST1348 | D31: PROD99 | E31: STORE3 | F31: 4 | G31: 451.67 | H31: 0.15 | I31: Credit Card | J31: 1535.678 | L31: =Table1[[#This Row],[Unit_Price]]*(1-Table1[[#This Row],[Discount]]) -> 383.9195 | M31: =Table1[[#This Row],[Total_Amount]]/L31 -> 4
A32: SALE30 | B32: 45217 | C32: CUST1028 | D32: PROD5 | E32: STORE19 | F32: 1 | G32: 429.38 | H32: 0.13 | I32: PayPal | J32: 373.5606 | L32: =Table1[[#This Row],[Unit_Price]]*(1-Table1[[#This Row],[Discount]]) -> 373.5606 | M32: =Table1[[#This Row],[Total_Amount]]/L32 -> 1
A33: SALE31 | B33: 45593 | C33: CUST1412 | D33: PROD53 | E33: STORE12 | F33: 2 | G33: 148.96 | H33: 0.03 | I33: COD | J33: 288.9824 | L33: =Table1[[#This Row],[Unit_Price]]*(1-Table1[[#This Row],[Discount]]) -> 144.4912 | M33: =Table1[[#This Row],[Total_Amount]]/L33 -> 2
A34: SALE32 | B34: 45597 | C34: CUST1398 | D34: PROD75 | E34: STORE8 | F34: 4 | G34: 313.83 | H34: 0.08 | I34: Credit Card | J34: 1154.8944 | L34: =Table1[[#This Row],[Unit_Price]]*(1-Table1[[#This Row],[Discount]]) -> 288.7236 | M34: =Table1[[#This Row],[Total_Amount]]/L34 -> 4
A35: SALE33 | B35: 45620 | C35: CUST1453 | D35: PROD12 | E35: STORE6 | F35: 2 | G35: 717.31 | H35: 0.15 | I35: Credit Card | J35: 1219.427 | L35: =Table1[[#This Row],[Unit_Price]]*(1-Table1[[#This Row],[Discount]]) -> 609.7135 | M35: =Table1[[#This Row],[Total_Amount]]/L35 -> 2
A36: SALE34 | B36: 45215 | C36: CUST1344 | D36: PROD79 | E36: STORE1 | F36: 3 | G36: 873.22 | H36: 0.18 | I36: Credit Card | J36: 2148.1212 | L36: =Table1[[#This Row],[Unit_Price]]*(1-Table1[[#This Row],[Discount]]) -> 716.0404 | M36: =Table1[[#This Row],[Total_Amount]]/L36 -> 3
A37: SALE35 | B37: 45878 | C37: CUST1218 | D37: PROD16 | E37: STORE3 | F37: 4 | G37: 109.36 | H37: 0.19 | I37: COD | J37: 354.3264 | L37: =Table1[[#This Row],[Unit_Price]]*(1-Table1[[#This Row],[Discount]]) -> 88.5816 | M37: =Table1[[#This Row],[Total_Amount]]/L37 -> 4
A38: SALE36 | B38: 45635 | C38: CUST1086 | D38: PROD5 | E38: STORE7 | F38: 3 | G38: 559.52 | H38: 0.16 | I38: PayPal | J38: 1409.9904 | L38: =Table1[[#This Row],[Unit_Price]]*(1-Table1[[#This Row],[Discount]]) -> 469.9968 | M38: =Table1[[#This Row],[Total_Amount]]/L38 -> 3
A39: SALE37 | B39: 45329 | C39: CUST1492 | D39: PROD10 | E39: STORE17 | F39: 3 | G39: 121.76 | H39: 0.27 | I39: PayPal | J39: 266.6544 | L39: =Table1[[#This Row],[Unit_Price]]*(1-Table1[[#This Row],[Discount]]) -> 88.8848 | M39: =Table1[[#This Row],[Total_Amount]]/L39 -> 3
A40: SALE38 | B40: 45378 | C40: CUST1189 | D40: PROD33 | E40: STORE13 | F40: 4 | G40: 735.32 | H40: 0.06 | I40: COD | J40: 2764.8032 | L40: =Table1[[#This Row],[Unit_Price]]*(1-Table1[[#This Row],[Discount]]) -> 691.2008 | M40: =Table1[[#This Row],[Total_Amount]]/L40 -> 4
... A45: SALE43 | B45: 45677 | C45: CUST1084 | D45: PROD33 | E45: STORE17 | F45: 3 | G45: 863.11 | H45: 0.28 | I45: PayPal | J45: 1864.3176 | L45: =Table1[[#This Row],[Unit_Price]]*(1-Table1[[#This Row],[Discount]]) -> 621.4392 | M45: =Table1[[#This Row],[Total_Amount]]/L45 -> 3
A46: SALE44 | B46: 45538 | C46: CUST1203 | D46: PROD43 | E46: STORE12 | F46: 2 | G46: 209.32 | H46: 0.23 | I46: COD | J46: 322.3528
A47: SALE45 | B47: 45606 | C47: CUST1470 | D47: PROD59 | E47: STORE8 | F47: 4 | G47: 288.6 | H47: 0.09 | I47: PayPal | J47: 1050.504
A48: SALE46 | B48: 45570 | C48: CUST1070 | D48: PROD78 | E48: STORE16 | F48: 1 | G48: 418.69 | H48: 0.06 | I48: PayPal | J48: 393.5686
A49: SALE47 | B49: 45466 | C49: CUST1008 | D49: PROD30 | E49: STORE11 | F49: 1 | G49: 135.78 | H49: 0.14 | I49: PayPal | J49: 116.7708
...

Sheet Analysis- Unit Price
A1: Unit Price Analysis
A3: Mean | B3: 513.58279
A4: Standard Error | B4: 6.3134988
A5: Median | B5: 522.43
A6: Mode | B6: 871.34
A7: Standard Deviation | B7: 282.34825
A8: Sample Variance | B8: 79720.534
A9: Kurtosis | B9: -1.1931883
A10: Skewness | B10: -0.034813907
A11: Range | B11: 979.8
A12: Minimum | B12: 20.09
A13: Maximum | B13: 999.89
A14: Sum | B14: 1027165.6
... A16: Confidence Level(95.0%) | B16: 12.381727

Sheet Histogram - Total Amount
A1: Bin | B1: Frequency | C1: Cumulative % | D1: Bin | E1: Frequency | F1: Cumulative %
A2: 18.459 | B2: 1 | C2: 0.0005 | D2: 637.28824 | E2: 124 | F2: 0.062
A3: 106.86318 | B3: 99 | C3: 0.05 | D3: 372.07571 | E3: 115 | F3: 0.1195
A4: 195.26735 | B4: 108 | C4: 0.104 | D4: 195.26735 | E4: 108 | F4: 0.1735
A5: 283.67153 | B5: 105 | C5: 0.1565 | D5: 548.88406 | E5: 108 | F5: 0.2275
A6: 372.07571 | B6: 115 | C6: 0.214 | D6: 283.67153 | E6: 105 | F6: 0.28
A7: 460.47989 | B7: 103 | C7: 0.2655 | D7: 460.47989 | E7: 103 | F7: 0.3315
A8: 548.88406 | B8: 108 | C8: 0.3195 | D8: 106.86318 | E8: 99 | F8: 0.381
A9: 637.28824 | B9: 124 | C9: 0.3815 | D9: 814.0966 | E9: 97 | F9: 0.4295
A10: 725.69242 | B10: 91 | C10: 0.427 | D10: 725.69242 | E10: 91 | F10: 0.475
A11: 814.0966 | B11: 97 | C11: 0.4755 | D11: 902.50077 | E11: 77 | F11: 0.5135
A12: 902.50077 | B12: 77 | C12: 0.514 | D12: 990.90495 | E12: 72 | F12: 0.5495
A13: 990.90495 | B13: 72 | C13: 0.55 | D13: 1256.1175 | E13: 71 | F13: 0.585
... A45: 3819.8386 | B45: 3 | C45: 0.9995 | D45: 3731.4344 | E45: 1 | F45: 0.9995
A46: More | B46: 1 | C46: 1 | D46: More | E46: 1 | F46: 1

Sheet Analysis - Total Amount
A1: Column1
A3: Mean | B3: 1087.1973
A4: Standard Error | B4: 18.327237
A5: Median | B5: 868.7182
A6: Mode | B6: #N/A
A7: Standard Deviation | B7: 819.61896
A8: Sample Variance | B8: 671775.25
A9: Kurtosis | B9: 0.045826153
A10: Skewness | B10: 0.87904704
A11: Range | B11: 3889.7838
A12: Minimum | B12: 18.459
A13: Maximum | B13: 3908.2428
A14: Sum | B14: 2174394.7
A15: Count | B15: 2000
A16: Largest(1) | B16: 3908.2428
A17: Smallest(1) | B17: 18.459
A18: Confidence Level(95.0%) | B18: 35.942487

Sheet Sales_Fact (2)
A1: Sales_ID | B1: Order_Date | C1: Customer_ID | D1: Product_ID | E1: Store_ID | F1: Quantity | G1: Unit_Price | H1: Discount | I1: Payment_Type | J1: Total_Amount | K1: Name | L1: Age | M1: Age Group | N1: Gender | O1: City | P1: State | Q1: Country | R1: Loyalty_Level | S1: Store_Name | T1: Region | U1: City2 | V1: Store_Type | W1: Product_Name | X1: Category | Y1: Sub_Category | Z1: Brand | AA1: Cost | AB1: Stock
A2: SALE0 | B2: 45480 | C2: CUST1409 | D2: PROD97 | E2: STORE3 | F2: 1 | G2: 218.04 | H2: 0.09 | I2: Credit Card | J2: 198.4164 | K2: =_xlfn.XLOOKUP(Table17[[#This Row],[Customer_ID]],Customer_Dim!A:A,Customer_Dim!B:B,"False Data") -> Sarah Smith | L2: =_xlfn.XLOOKUP(Table17[[#This Row],[Customer_ID]],Customer_Dim!A:A,Customer_Dim!C:C,"False Data") -> 55 | M2: {=_xlfn.IFS(Table9[[#This Row],[Age]]<=35,"Youth",Table9[[#This Row],[Age]]<=55,"Adult",Table9[[#This Row],[Age]]>55,"Senior")} -> Adult | N2: =_xlfn.XLOOKUP(Table17[[#This Row],[Customer_ID]],Customer_Dim!A:A,Customer_Dim!D:D,"False Data") -> Male | O2: =_xlfn.XLOOKUP(Table17[[#This Row],[Customer_ID]],Customer_Dim!A:A,Customer_Dim!E:E,"False Data") -> Kathleenport | P2: =_xlfn.XLOOKUP(Table17[[#This Row],[Customer_ID]],Customer_Dim!A:A,Customer_Dim!F:F,"False Data") -> Wyoming | Q2: =_xlfn.XLOOKUP(Table17[[#This Row],[Customer_ID]],Customer_Dim!A:A,Customer_Dim!G:G,"False Data") -> USA | R2: =_xlfn.XLOOKUP(Table17[[#This Row],[Customer_ID]],Customer_Dim!A:A,Customer_Dim!H:H,"False Data") -> Gold | S2: =_xlfn.XLOOKUP(Table17[[#This Row],[Store_ID]],Store_Dim!A:A,Store_Dim!B:B) -> Johnson-Wright | T2: =_xlfn.XLOOKUP(Table17[[#This Row],[Store_ID]],Store_Dim!A:A,Store_Dim!C:C) -> North | U2: =_xlfn.XLOOKUP(Table17[[#This Row],[Store_ID]],Store_Dim!A:A,Store_Dim!D:D) -> Hoodberg | V2: =_xlfn.XLOOKUP(Table17[[#This Row],[Store_ID]],Store_Dim!A:A,Store_Dim!E:E) -> Outlet | W2: =_xlfn.XLOOKUP(Table17[[#This Row],[Product_ID]],Product_Dim!A:A,Product_Dim!B:B) -> Cricket Bat | X2: =_xlfn.XLOOKUP(Table17[[#This Row],[Product_ID]],Product_Dim!A:A,Product_Dim!C:C) -> Sports | Y2: =_xlfn.XLOOKUP(Table17[[#This Row],[Product_ID]],Product_Dim!A:A,Product_Dim!D:D) -> Team Sports | Z2: =_xlfn.XLOOKUP(Table17[[#This Row],[Product_ID]],Product_Dim!A:A,Product_Dim!E:E) -> Khan LLC | AA2: =_xlfn.XLOOKUP(Table17[[#This Row],[Product_ID]],Product_Dim!A:A,Product_Dim!F:F) -> 245.98 | AB2: =_xlfn.XLOOKUP(Table17[[#This Row],[Product_ID]],Product_Dim!A:A,Product_Dim!G:G) -> 471
A3: SALE1 | B3: 45285 | C3: CUST1467 | D3: PROD74 | E3: STORE17 | F3: 3 | G3: 104.47 | H3: 0.27 | I3: PayPal | J3: 228.7893 | K3: =_xlfn.XLOOKUP(Table17[[#This Row],[Customer_ID]],Customer_Dim!A:A,Customer_Dim!B:B,"False Data") -> Michael Foley | L3: =_xlfn.XLOOKUP(Table17[[#This Row],[Customer_ID]],Customer_Dim!A:A,Customer_Dim!C:C,"False Data") -> 63 | M3: {=_xlfn.IFS(Table9[[#This Row],[Age]]<=35,"Youth",Table9[[#This Row],[Age]]<=55,"Adult",Table9[[#This Row],[Age]]>55,"Senior")} -> Senior | N3: =_xlfn.XLOOKUP(Table17[[#This Row],[Customer_ID]],Customer_Dim!A:A,Customer_Dim!D:D,"False Data") -> Female | O3: =_xlfn.XLOOKUP(Table17[[#This Row],[Customer_ID]],Customer_Dim!A:A,Customer_Dim!E:E,"False Data") -> Oneillfurt | P3: =_xlfn.XLOOKUP(Table17[[#This Row],[Customer_ID]],Customer_Dim!A:A,Customer_Dim!F:F,"False Data") -> Vermont | Q3: =_xlfn.XLOOKUP(Table17[[#This Row],[Customer_ID]],Customer_Dim!A:A,Customer_Dim!G:G,"False Data") -> USA | R3: =_xlfn.XLOOKUP(Table17[[#This Row],[Customer_ID]],Customer_Dim!A:A,Customer_Dim!H:H,"False Data") -> Gold | S3: =_xlfn.XLOOKUP(Table17[[#This Row],[Store_ID]],Store_Dim!A:A,Store_Dim!B:B) -> Holloway Ltd | T3: =_xlfn.XLOOKUP(Table17[[#This Row],[Store_ID]],Store_Dim!A:A,Store_Dim!C:C) -> North | U3: =_xlfn.XLOOKUP(Table17[[#This Row],[Store_ID]],Store_Dim!A:A,Store_Dim!D:D) -> Bensonhaven | V3: =_xlfn.XLOOKUP(Table17[[#This Row],[Store_ID]],Store_Dim!A:A,Store_Dim!E:E) -> Flagship | W3: =_xlfn.XLOOKUP(Table17[[#This Row],[Product_ID]],Product_Dim!A:A,Product_Dim!B:B) -> Bluetooth Car Audio System | X3: =_xlfn.XLOOKUP(Table17[[#This Row],[Product_ID]],Product_Dim!A:A,Product_Dim!C:C) -> Electronics | Y3: =_xlfn.XLOOKUP(Table17[[#This Row],[Product_ID]],Product_Dim!A:A,Product_Dim!D:D) -> Audio | Z3: =_xlfn.XLOOKUP(Table17[[#This Row],[Product_ID]],Product_Dim!A:A,Product_Dim!E:E) -> Bruce-Bowen | AA3: =_xlfn.XLOOKUP(Table17[[#This Row],[Product_ID]],Product_Dim!A:A,Product_Dim!F:F) -> 403.71 | AB3: =_xlfn.XLOOKUP(Table17[[#This Row],[Product_ID]],Product_Dim!A:A,Product_Dim!G:G) -> 159
A4: SALE2 | B4: 45446 | C4: CUST1056 | D4: PROD49 | E4: STORE8 | F4: 4 | G4: 914.05 | H4: 0.25 | I4: Credit Card | J4: 2742.15 | K4: =_xlfn.XLOOKUP(Table17[[#This Row],[Customer_ID]],Customer_Dim!A:A,Customer_Dim!B:B,"False Data") -> Christopher Sutton | L4: =_xlfn.XLOOKUP(Table17[[#This Row],[Customer_ID]],Customer_Dim!A:A,Customer_Dim!C:C,"False Data") -> 49 | M4: {=_xlfn.IFS(Table9[[#This Row],[Age]]<=35,"Youth",Table9[[#This Row],[Age]]<=55,"Adult",Table9[[#This Row],[Age]]>55,"Senior")} -> Adult | N4: =_xlfn.XLOOKUP(Table17[[#This Row],[Customer_ID]],Customer_Dim!A:A,Customer_Dim!D:D,"False Data") -> Female | O4: =_xlfn.XLOOKUP(Table17[[#This Row],[Customer_ID]],Customer_Dim!A:A,Customer_Dim!E:E,"False Data") -> Deborahberg | P4: =_xlfn.XLOOKUP(Table17[[#This Row],[Customer_ID]],Customer_Dim!A:A,Customer_Dim!F:F,"False Data") -> Pennsylvania | Q4: =_xlfn.XLOOKUP(Table17[[#This Row],[Customer_ID]],Customer_Dim!A:A,Customer_Dim!G:G,"False Data") -> USA | R4: =_xlfn.XLOOKUP(Table17[[#This Row],[Customer_ID]],Customer_Dim!A:A,Customer_Dim!H:H,"False Data") -> Gold | S4: =_xlfn.XLOOKUP(Table17[[#This Row],[Store_ID]],Store_Dim!A:A,Store_Dim!B:B) -> Bean, Jones and Park | T4: =_xlfn.XLOOKUP(Table17[[#This Row],[Store_ID]],Store_Dim!A:A,Store_Dim!C:C) -> West | U4: =_xlfn.XLOOKUP(Table17[[#This Row],[Store_ID]],Store_Dim!A:A,Store_Dim!D:D) -> Thompsonborough | V4: =_xlfn.XLOOKUP(Table17[[#This Row],[Store_ID]],Store_Dim!A:A,Store_Dim!E:E) -> Online | W4: =_xlfn.XLOOKUP(Table17[[#This Row],[Product_ID]],Product_Dim!A:A,Product_Dim!B:B) -> Men's Roll-On Perfume | X4: =_xlfn.XLOOKUP(Table17[[#This Row],[Product_ID]],Product_Dim!A:A,Product_Dim!C:C) -> Beauty | Y4: =_xlfn.XLOOKUP(Table17[[#This Row],[Product_ID]],Product_Dim!A:A,Product_Dim!D:D) -> Fragrance | Z4: =_xlfn.XLOOKUP(Table17[[#This Row],[Product_ID]],Product_Dim!A:A,Product_Dim!E:E) -> Sullivan and Sons | AA4: =_xlfn.XLOOKUP(Table17[[#This Row],[Product_ID]],Product_Dim!A:A,Product_Dim!F:F) -> 43.29 | AB4: =_xlfn.XLOOKUP(Table17[[#This Row],[Product_ID]],Product_Dim!A:A,Product_Dim!G:G) -> 267
A5: SALE3 | B5: 45259 | C5: CUST1346 | D5: PROD76 | E5: STORE8 | F5: 1 | G5: 921.51 | H5: 0.16 | I5: COD | J5: 774.0684 | K5: =_xlfn.XLOOKUP(Table17[[#This Row],[Customer_ID]],Customer_Dim!A:A,Customer_Dim!B:B,"False Data") -> John Jordan | L5: =_xlfn.XLOOKUP(Table17[[#This Row],[Customer_ID]],Customer_Dim!A:A,Customer_Dim!C:C,"False Data") -> 58 | M5: {=_xlfn.IFS(Table9[[#This Row],[Age]]<=35,"Youth",Table9[[#This Row],[Age]]<=55,"Adult",Table9[[#This Row],[Age]]>55,"Senior")} -> Senior | N5: =_xlfn.XLOOKUP(Table17[[#This Row],[Customer_ID]],Customer_Dim!A:A,Customer_Dim!D:D,"False Data") -> Female | O5: =_xlfn.XLOOKUP(Table17[[#This Row],[Customer_ID]],Customer_Dim!A:A,Customer_Dim!E:E,"False Data") -> Port Crystalberg | P5: =_xlfn.XLOOKUP(Table17[[#This Row],[Customer_ID]],Customer_Dim!A:A,Customer_Dim!F:F,"False Data") -> Tennessee | Q5: =_xlfn.XLOOKUP(Table17[[#This Row],[Customer_ID]],Customer_Dim!A:A,Customer_Dim!G:G,"False Data") -> USA | R5: =_xlfn.XLOOKUP(Table17[[#This Row],[Customer_ID]],Customer_Dim!A:A,Customer_Dim!H:H,"False Data") -> Platinum | S5: =_xlfn.XLOOKUP(Table17[[#This Row],[Store_ID]],Store_Dim!A:A,Store_Dim!B:B) -> Bean, Jones and Park | T5: =_xlfn.XLOOKUP(Table17[[#This Row],[Store_ID]],Store_Dim!A:A,Store_Dim!C:C) -> West | U5: =_xlfn.XLOOKUP(Table17[[#This Row],[Store_ID]],Store_Dim!A:A,Store_Dim!D:D) -> Thompsonborough | V5: =_xlfn.XLOOKUP(Table17[[#This Row],[Store_ID]],Store_Dim!A:A,Store_Dim!E:E) -> Online | W5: =_xlfn.XLOOKUP(Table17[[#This Row],[Product_ID]],Product_Dim!A:A,Product_Dim!B:B) -> Wireless Mouse | X5: =_xlfn.XLOOKUP(Table17[[#This Row],[Product_ID]],Product_Dim!A:A,Product_Dim!C:C) -> Electronics | Y5: =_xlfn.XLOOKUP(Table17[[#This Row],[Product_ID]],Product_Dim!A:A,Product_Dim!D:D) -> Computer | Z5: =_xlfn.XLOOKUP(Table17[[#This Row],[Product_ID]],Product_Dim!A:A,Product_Dim!E:E) -> Larson Ltd | AA5: =_xlfn.XLOOKUP(Table17[[#This Row],[Product_ID]],Product_Dim!A:A,Product_Dim!F:F) -> 392.89 | AB5: =_xlfn.XLOOKUP(Table17[[#This Row],[Product_ID]],Product_Dim!A:A,Product_Dim!G:G) -> 320
A6: SALE4 | B6: 45297 | C6: CUST1493 | D6: PROD59 | E6: STORE5 | F6: 3 | G6: 745.3 | H6: 0.18 | I6: Credit Card | J6: 1833.438 | K6: =_xlfn.XLOOKUP(Table17[[#This Row],[Customer_ID]],Customer_Dim!A:A,Customer_Dim!B:B,"False Data") -> Amanda Powell | L6: =_xlfn.XLOOKUP(Table17[[#This Row],[Customer_ID]],Customer_Dim!A:A,Customer_Dim!C:C,"False Data") -> 28 | M6: {=_xlfn.IFS(Table9[[#This Row],[Age]]<=35,"Youth",Table9[[#This Row],[Age]]<=55,"Adult",Table9[[#This Row],[Age]]>55,"Senior")} -> Youth | N6: =_xlfn.XLOOKUP(Table17[[#This Row],[Customer_ID]],Customer_Dim!A:A,Customer_Dim!D:D,"False Data") -> Male | O6: =_xlfn.XLOOKUP(Table17[[#This Row],[Customer_ID]],Customer_Dim!A:A,Customer_Dim!E:E,"False Data") -> South William | P6: =_xlfn.XLOOKUP(Table17[[#This Row],[Customer_ID]],Customer_Dim!A:A,Customer_Dim!F:F,"False Data") -> Alabama | Q6: =_xlfn.XLOOKUP(Table17[[#This Row],[Customer_ID]],Customer_Dim!A:A,Customer_Dim!G:G,"False Data") -> USA | R6: =_xlfn.XLOOKUP(Table17[[#This Row],[Customer_ID]],Customer_Dim!A:A,Customer_Dim!H:H,"False Data") -> Silver | S6: =_xlfn.XLOOKUP(Table17[[#This Row],[Store_ID]],Store_Dim!A:A,Store_Dim!B:B) -> Gray Ltd | T6: =_xlfn.XLOOKUP(Table17[[#This Row],[Store_ID]],Store_Dim!A:A,Store_Dim!C:C) -> North | U6: =_xlfn.XLOOKUP(Table17[[#This Row],[Store_ID]],Store_Dim!A:A,Store_Dim!D:D) -> New Michaelchester | V6: =_xlfn.XLOOKUP(Table17[[#This Row],[Store_ID]],Store_Dim!A:A,Store_Dim!E:E) -> Outlet | W6: =_xlfn.XLOOKUP(Table17[[#This Row],[Product_ID]],Product_Dim!A:A,Product_Dim!B:B) -> Men's Hair Styling Gel | X6: =_xlfn.XLOOKUP(Table17[[#This Row],[Product_ID]],Product_Dim!A:A,Product_Dim!C:C) -> Beauty | Y6: =_xlfn.XLOOKUP(Table17[[#This Row],[Product_ID]],Product_Dim!A:A,Product_Dim!D:D) -> Haircare | Z6: =_xlfn.XLOOKUP(Table17[[#This Row],[Product_ID]],Product_Dim!A:A,Product_Dim!E:E) -> Cline-Mccarthy | AA6: =_xlfn.XLOOKUP(Table17[[#This Row],[Product_ID]],Product_Dim!A:A,Product_Dim!F:F) -> 17.31 | AB6: =_xlfn.XLOOKUP(Table17[[#This Row],[Product_ID]],Product_Dim!A:A,Product_Dim!G:G) -> 399
A7: SALE5 | B7: 45499 | C7: CUST1116 | D7: PROD15 | E7: STORE7 | F7: 3 | G7: 147.01 | H7: 0.19 | I7: COD | J7: 357.2343 | K7: =_xlfn.XLOOKUP(Table17[[#This Row],[Customer_ID]],Customer_Dim!A:A,Customer_Dim!B:B,"False Data") -> Anthony Phillips | L7: =_xlfn.XLOOKUP(Table17[[#This Row],[Customer_ID]],Customer_Dim!A:A,Customer_Dim!C:C,"False Data") -> 18 | M7: {=_xlfn.IFS(Table9[[#This Row],[Age]]<=35,"Youth",Table9[[#This Row],[Age]]<=55,"Adult",Table9[[#This Row],[Age]]>55,"Senior")} -> Youth | N7: =_xlfn.XLOOKUP(Table17[[#This Row],[Customer_ID]],Customer_Dim!A:A,Customer_Dim!D:D,"False Data") -> Female | O7: =_xlfn.XLOOKUP(Table17[[#This Row],[Customer_ID]],Customer_Dim!A:A,Customer_Dim!E:E,"False Data") -> North Davidport | P7: =_xlfn.XLOOKUP(Table17[[#This Row],[Customer_ID]],Customer_Dim!A:A,Customer_Dim!F:F,"False Data") -> Rhode Island | Q7: =_xlfn.XLOOKUP(Table17[[#This Row],[Customer_ID]],Customer_Dim!A:A,Customer_Dim!G:G,"False Data") -> USA | R7: =_xlfn.XLOOKUP(Table17[[#This Row],[Customer_ID]],Customer_Dim!A:A,Customer_Dim!H:H,"False Data") -> Platinum | S7: =_xlfn.XLOOKUP(Table17[[#This Row],[Store_ID]],Store_Dim!A:A,Store_Dim!B:B) -> Martinez-Mullins | T7: =_xlfn.XLOOKUP(Table17[[#This Row],[Store_ID]],Store_Dim!A:A,Store_Dim!C:C) -> South | U7: =_xlfn.XLOOKUP(Table17[[#This Row],[Store_ID]],Store_Dim!A:A,Store_Dim!D:D) -> Williamsfurt | V7: =_xlfn.XLOOKUP(Table17[[#This Row],[Store_ID]],Store_Dim!A:A,Store_Dim!E:E) -> Online | W7: =_xlfn.XLOOKUP(Table17[[#This Row],[Product_ID]],Product_Dim!A:A,Product_Dim!B:B) -> 4K Home Projector | X7: =_xlfn.XLOOKUP(Table17[[#This Row],[Product_ID]],Product_Dim!A:A,Product_Dim!C:C) -> Electronics | Y7: =_xlfn.XLOOKUP(Table17[[#This Row],[Product_ID]],Product_Dim!A:A,Product_Dim!D:D) -> Appliances | Z7: =_xlfn.XLOOKUP(Table17[[#This Row],[Product_ID]],Product_Dim!A:A,Product_Dim!E:E) -> Thomas LLC | AA7: =_xlfn.XLOOKUP(Table17[[#This Row],[Product_ID]],Product_Dim!A:A,Product_Dim!F:F) -> 465.34 | AB7: =_xlfn.XLOOKUP(Table17[[#This Row],[Product_ID]],Product_Dim!A:A,Product_Dim!G:G) -> 301
A8: SALE6 | B8: 45850 | C8: CUST1016 | D8: PROD56 | E8: STORE4 | F8: 2 | G8: 785.31 | H8: 0.15 | I8: PayPal | J8: 1335.027 | K8: =_xlfn.XLOOKUP(Table17[[#This Row],[Customer_ID]],Customer_Dim!A:A,Customer_Dim!B:B,"False Data") -> John Scott | L8: =_xlfn.XLOOKUP(Table17[[#This Row],[Customer_ID]],Customer_Dim!A:A,Customer_Dim!C:C,"False Data") -> 24 | M8: {=_xlfn.IFS(Table9[[#This Row],[Age]]<=35,"Youth",Table9[[#This Row],[Age]]<=55,"Adult",Table9[[#This Row],[Age]]>55,"Senior")} -> Youth | N8: =_xlfn.XLOOKUP(Table17[[#This Row],[Customer_ID]],Customer_Dim!A:A,Customer_Dim!D:D,"False Data") -> Female | O8: =_xlfn.XLOOKUP(Table17[[#This Row],[Customer_ID]],Customer_Dim!A:A,Customer_Dim!E:E,"False Data") -> South Christopher | P8: =_xlfn.XLOOKUP(Table17[[#This Row],[Customer_ID]],Customer_Dim!A:A,Customer_Dim!F:F,"False Data") -> Pennsylvania | Q8: =_xlfn.XLOOKUP(Table17[[#This Row],[Customer_ID]],Customer_Dim!A:A,Customer_Dim!G:G,"False Data") -> USA | R8: =_xlfn.XLOOKUP(Table17[[#This Row],[Customer_ID]],Customer_Dim!A:A,Customer_Dim!H:H,"False Data") -> Bronze | S8: =_xlfn.XLOOKUP(Table17[[#This Row],[Store_ID]],Store_Dim!A:A,Store_Dim!B:B) -> Alexander Group | T8: =_xlfn.XLOOKUP(Table17[[#This Row],[Store_ID]],Store_Dim!A:A,Store_Dim!C:C) -> South | U8: =_xlfn.XLOOKUP(Table17[[#This Row],[Store_ID]],Store_Dim!A:A,Store_Dim!D:D) -> Port Sharon | V8: =_xlfn.XLOOKUP(Table17[[#This Row],[Store_ID]],Store_Dim!A:A,Store_Dim!E:E) -> Online | W8: =_xlfn.XLOOKUP(Table17[[#This Row],[Product_ID]],Product_Dim!A:A,Product_Dim!B:B) -> Premium Blanket Throw | X8: =_xlfn.XLOOKUP(Table17[[#This Row],[Product_ID]],Product_Dim!A:A,Product_Dim!C:C) -> Home | Y8: =_xlfn.XLOOKUP(Table17[[#This Row],[Product_ID]],Product_Dim!A:A,Product_Dim!D:D) -> Decor | Z8: =_xlfn.XLOOKUP(Table17[[#This Row],[Product_ID]],Product_Dim!A:A,Product_Dim!E:E) -> Hernandez, Kennedy and Porter | AA8: =_xlfn.XLOOKUP(Table17[[#This Row],[Product_ID]],Product_Dim!A:A,Product_Dim!F:F) -> 461.47 | AB8: =_xlfn.XLOOKUP(Table17[[#This Row],[Product_ID]],Product_Dim!A:A,Product_Dim!G:G) -> 190
A9: SALE7 | B9: 45248 | C9: CUST1152 | D9: PROD70 | E9: STORE8 | F9: 4 | G9: 342.39 | H9: 0.23 | I9: PayPal | J9: 1054.5612 | K9: =_xlfn.XLOOKUP(Table17[[#This Row],[Customer_ID]],Customer_Dim!A:A,Customer_Dim!B:B,"False Data") -> Patrick Roberts | L9: =_xlfn.XLOOKUP(Table17[[#This Row],[Customer_ID]],Customer_Dim!A:A,Customer_Dim!C:C,"False Data") -> 41 | M9: {=_xlfn.IFS(Table9[[#This Row],[Age]]<=35,"Youth",Table9[[#This Row],[Age]]<=55,"Adult",Table9[[#This Row],[Age]]>55,"Senior")} -> Adult | N9: =_xlfn.XLOOKUP(Table17[[#This Row],[Customer_ID]],Customer_Dim!A:A,Customer_Dim!D:D,"False Data") -> Female | O9: =_xlfn.XLOOKUP(Table17[[#This Row],[Customer_ID]],Customer_Dim!A:A,Customer_Dim!E:E,"False Data") -> Jaredville | P9: =_xlfn.XLOOKUP(Table17[[#This Row],[Customer_ID]],Customer_Dim!A:A,Customer_Dim!F:F,"False Data") -> Missouri | Q9: =_xlfn.XLOOKUP(Table17[[#This Row],[Customer_ID]],Customer_Dim!A:A,Customer_Dim!G:G,"False Data") -> USA | R9: =_xlfn.XLOOKUP(Table17[[#This Row],[Customer_ID]],Customer_Dim!A:A,Customer_Dim!H:H,"False Data") -> Platinum | S9: =_xlfn.XLOOKUP(Table17[[#This Row],[Store_ID]],Store_Dim!A:A,Store_Dim!B:B) -> Bean, Jones and Park | T9: =_xlfn.XLOOKUP(Table17[[#This Row],[Store_ID]],Store_Dim!A:A,Store_Dim!C:C) -> West | U9: =_xlfn.XLOOKUP(Table17[[#This Row],[Store_ID]],Store_Dim!A:A,Store_Dim!D:D) -> Thompsonborough | V9: =_xlfn.XLOOKUP(Table17[[#This Row],[Store_ID]],Store_Dim!A:A,Store_Dim!E:E) -> Online | W9: =_xlfn.XLOOKUP(Table17[[#This Row],[Product_ID]],Product_Dim!A:A,Product_Dim!B:B) -> Kitchen Storage Rack | X9: =_xlfn.XLOOKUP(Table17[[#This Row],[Product_ID]],Product_Dim!A:A,Product_Dim!C:C) -> Home | Y9: =_xlfn.XLOOKUP(Table17[[#This Row],[Product_ID]],Product_Dim!A:A,Product_Dim!D:D) -> Storage | Z9: =_xlfn.XLOOKUP(Table17[[#This Row],[Product_ID]],Product_Dim!A:A,Product_Dim!E:E) -> Duran Group | AA9: =_xlfn.XLOOKUP(Table17[[#This Row],[Product_ID]],Product_Dim!A:A,Product_Dim!F:F) -> 138.05 | AB9: =_xlfn.XLOOKUP(Table17[[#This Row],[Product_ID]],Product_Dim!A:A,Product_Dim!G:G) -> 89
A10: SALE8 | B10: 45781 | C10: CUST1187 | D10: PROD99 | E10: STORE5 | F10: 3 | G10: 448.25 | H10: 0.07 | I10: PayPal | J10: 1250.6175 | K10: =_xlfn.XLOOKUP(Table17[[#This Row],[Customer_ID]],Customer_Dim!A:A,Customer_Dim!B:B,"False Data") -> Dr. Suzanne Bullock | L10: =_xlfn.XLOOKUP(Table17[[#This Row],[Customer_ID]],Customer_Dim!A:A,Customer_Dim!C:C,"False Data") -> 60 | M10: {=_xlfn.IFS(Table9[[#This Row],[Age]]<=35,"Youth",Table9[[#This Row],[Age]]<=55,"Adult",Table9[[#This Row],[Age]]>55,"Senior")} -> Senior | N10: =_xlfn.XLOOKUP(Table17[[#This Row],[Customer_ID]],Customer_Dim!A:A,Customer_Dim!D:D,"False Data") -> Female | O10: =_xlfn.XLOOKUP(Table17[[#This Row],[Customer_ID]],Customer_Dim!A:A,Customer_Dim!E:E,"False Data") -> Lake Blaketon | P10: =_xlfn.XLOOKUP(Table17[[#This Row],[Customer_ID]],Customer_Dim!A:A,Customer_Dim!F:F,"False Data") -> Alabama | Q10: =_xlfn.XLOOKUP(Table17[[#This Row],[Customer_ID]],Customer_Dim!A:A,Customer_Dim!G:G,"False Data") -> USA | R10: =_xlfn.XLOOKUP(Table17[[#This Row],[Customer_ID]],Customer_Dim!A:A,Customer_Dim!H:H,"False Data") -> Platinum | S10: =_xlfn.XLOOKUP(Table17[[#This Row],[Store_ID]],Store_Dim!A:A,Store_Dim!B:B) -> Gray Ltd | T10: =_xlfn.XLOOKUP(Table17[[#This Row],[Store_ID]],Store_Dim!A:A,Store_Dim!C:C) -> North | U10: =_xlfn.XLOOKUP(Table17[[#This Row],[Store_ID]],Store_Dim!A:A,Store_Dim!D:D) -> New Michaelchester | V10: =_xlfn.XLOOKUP(Table17[[#This Row],[Store_ID]],Store_Dim!A:A,Store_Dim!E:E) -> Outlet | W10: =_xlfn.XLOOKUP(Table17[[#This Row],[Product_ID]],Product_Dim!A:A,Product_Dim!B:B) -> Stainless Steel Cookware Set | X10: =_xlfn.XLOOKUP(Table17[[#This Row],[Product_ID]],Product_Dim!A:A,Product_Dim!C:C) -> Home | Y10: =_xlfn.XLOOKUP(Table17[[#This Row],[Product_ID]],Product_Dim!A:A,Product_Dim!D:D) -> Kitchen | Z10: =_xlfn.XLOOKUP(Table17[[#This Row],[Product_ID]],Product_Dim!A:A,Product_Dim!E:E) -> Campbell Ltd | AA10: =_xlfn.XLOOKUP(Table17[[#This Row],[Product_ID]],Product_Dim!A:A,Product_Dim!F:F) -> 201.41 | AB10: =_xlfn.XLOOKUP(Table17[[#This Row],[Product_ID]],Product_Dim!A:A,Product_Dim!G:G) -> 146
A11: SALE9 | B11: 45869 | C11: CUST1464 | D11: PROD33 | E11: STORE0 | F11: 2 | G11: 873.17 | H11: 0.23 | I11: PayPal | J11: 1344.6818 | K11: =_xlfn.XLOOKUP(Table17[[#This Row],[Customer_ID]],Customer_Dim!A:A,Customer_Dim!B:B,"False Data") -> David Pierce | L11: =_xlfn.XLOOKUP(Table17[[#This Row],[Customer_ID]],Customer_Dim!A:A,Customer_Dim!C:C,"False Data") -> 45 | M11: {=_xlfn.IFS(Table9[[#This Row],[Age]]<=35,"Youth",Table9[[#This Row],[Age]]<=55,"Adult",Table9[[#This Row],[Age]]>55,"Senior")} -> Adult | N11: =_xlfn.XLOOKUP(Table17[[#This Row],[Customer_ID]],Customer_Dim!A:A,Customer_Dim!D:D,"False Data") -> Female | O11: =_xlfn.XLOOKUP(Table17[[#This Row],[Customer_ID]],Customer_Dim!A:A,Customer_Dim!E:E,"False Data") -> Grayland | P11: =_xlfn.XLOOKUP(Table17[[#This Row],[Customer_ID]],Customer_Dim!A:A,Customer_Dim!F:F,"False Data") -> Washington | Q11: =_xlfn.XLOOKUP(Table17[[#This Row],[Customer_ID]],Customer_Dim!A:A,Customer_Dim!G:G,"False Data") -> USA | R11: =_xlfn.XLOOKUP(Table17[[#This Row],[Customer_ID]],Customer_Dim!A:A,Customer_Dim!H:H,"False Data") -> Platinum | S11: =_xlfn.XLOOKUP(Table17[[#This Row],[Store_ID]],Store_Dim!A:A,Store_Dim!B:B) -> Rivera-Warner | T11: =_xlfn.XLOOKUP(Table17[[#This Row],[Store_ID]],Store_Dim!A:A,Store_Dim!C:C) -> East | U11: =_xlfn.XLOOKUP(Table17[[#This Row],[Store_ID]],Store_Dim!A:A,Store_Dim!D:D) -> Washingtonfurt | V11: =_xlfn.XLOOKUP(Table17[[#This Row],[Store_ID]],Store_Dim!A:A,Store_Dim!E:E) -> Flagship | W11: =_xlfn.XLOOKUP(Table17[[#This Row],[Product_ID]],Product_Dim!A:A,Product_Dim!B:B) -> Modern Wall Clock | X11: =_xlfn.XLOOKUP(Table17[[#This Row],[Product_ID]],Product_Dim!A:A,Product_Dim!C:C) -> Home | Y11: =_xlfn.XLOOKUP(Table17[[#This Row],[Product_ID]],Product_Dim!A:A,Product_Dim!D:D) -> Decor | Z11: =_xlfn.XLOOKUP(Table17[[#This Row],[Product_ID]],Product_Dim!A:A,Product_Dim!E:E) -> Weiss-Watson | AA11: =_xlfn.XLOOKUP(Table17[[#This Row],[Product_ID]],Product_Dim!A:A,Product_Dim!F:F) -> 179.77 | AB11: =_xlfn.XLOOKUP(Table17[[#This Row],[Product_ID]],Product_Dim!A:A,Product_Dim!G:G) -> 305
A12: SALE10 | B12: 45335 | C12: CUST1065 | D12: PROD24 | E12: STORE14 | F12: 1 | G12: 278.63 | H12: 0.07 | I12: Credit Card | J12: 259.1259 | K12: =_xlfn.XLOOKUP(Table17[[#This Row],[Customer_ID]],Customer_Dim!A:A,Customer_Dim!B:B,"False Data") -> Michael Thomas | L12: =_xlfn.XLOOKUP(Table17[[#This Row],[Customer_ID]],Customer_Dim!A:A,Customer_Dim!C:C,"False Data") -> 21 | M12: {=_xlfn.IFS(Table9[[#This Row],[Age]]<=35,"Youth",Table9[[#This Row],[Age]]<=55,"Adult",Table9[[#This Row],[Age]]>55,"Senior")} -> Youth | N12: =_xlfn.XLOOKUP(Table17[[#This Row],[Customer_ID]],Customer_Dim!A:A,Customer_Dim!D:D,"False Data") -> Female | O12: =_xlfn.XLOOKUP(Table17[[#This Row],[Customer_ID]],Customer_Dim!A:A,Customer_Dim!E:E,"False Data") -> Woodmouth | P12: =_xlfn.XLOOKUP(Table17[[#This Row],[Customer_ID]],Customer_Dim!A:A,Customer_Dim!F:F,"False Data") -> Nevada | Q12: =_xlfn.XLOOKUP(Table17[[#This Row],[Customer_ID]],Customer_Dim!A:A,Customer_Dim!G:G,"False Data") -> USA | R12: =_xlfn.XLOOKUP(Table17[[#This Row],[Customer_ID]],Customer_Dim!A:A,Customer_Dim!H:H,"False Data") -> Silver | S12: =_xlfn.XLOOKUP(Table17[[#This Row],[Store_ID]],Store_Dim!A:A,Store_Dim!B:B) -> Mcdonald Inc | T12: =_xlfn.XLOOKUP(Table17[[#This Row],[Store_ID]],Store_Dim!A:A,Store_Dim!C:C) -> South | U12: =_xlfn.XLOOKUP(Table17[[#This Row],[Store_ID]],Store_Dim!A:A,Store_Dim!D:D) -> Christopherland | V12: =_xlfn.XLOOKUP(Table17[[#This Row],[Store_ID]],Store_Dim!A:A,Store_Dim!E:E) -> Outlet | W12: =_xlfn.XLOOKUP(Table17[[#This Row],[Product_ID]],Product_Dim!A:A,Product_Dim!B:B) -> Foldable Camping Chair | X12: =_xlfn.XLOOKUP(Table17[[#This Row],[Product_ID]],Product_Dim!A:A,Product_Dim!C:C) -> Sports | Y12: =_xlfn.XLOOKUP(Table17[[#This Row],[Product_ID]],Product_Dim!A:A,Product_Dim!D:D) -> Outdoor | Z12: =_xlfn.XLOOKUP(Table17[[#This Row],[Product_ID]],Product_Dim!A:A,Product_Dim!E:E) -> Cook Ltd | AA12: =_xlfn.XLOOKUP(Table17[[#This Row],[Product_ID]],Product_Dim!A:A,Product_Dim!F:F) -> 166.06 | AB12: =_xlfn.XLOOKUP(Table17[[#This Row],[Product_ID]],Product_Dim!A:A,Product_Dim!G:G) -> 340
A13: SALE11 | B13: 45801 | C13: CUST1320 | D13: PROD39 | E13: STORE1 | F13: 4 | G13: 286.92 | H13: 0.17 | I13: Credit Card | J13: 952.5744 | K13: =_xlfn.XLOOKUP(Table17[[#This Row],[Customer_ID]],Customer_Dim!A:A,Customer_Dim!B:B,"False Data") -> Jessica Gonzalez | L13: =_xlfn.XLOOKUP(Table17[[#This Row],[Customer_ID]],Customer_Dim!A:A,Customer_Dim!C:C,"False Data") -> 34 | M13: {=_xlfn.IFS(Table9[[#This Row],[Age]]<=35,"Youth",Table9[[#This Row],[Age]]<=55,"Adult",Table9[[#This Row],[Age]]>55,"Senior")} -> Youth | N13: =_xlfn.XLOOKUP(Table17[[#This Row],[Customer_ID]],Customer_Dim!A:A,Customer_Dim!D:D,"False Data") -> Female | O13: =_xlfn.XLOOKUP(Table17[[#This Row],[Customer_ID]],Customer_Dim!A:A,Customer_Dim!E:E,"False Data") -> South Darrenland | P13: =_xlfn.XLOOKUP(Table17[[#This Row],[Customer_ID]],Customer_Dim!A:A,Customer_Dim!F:F,"False Data") -> Iowa | Q13: =_xlfn.XLOOKUP(Table17[[#This Row],[Customer_ID]],Customer_Dim!A:A,Customer_Dim!G:G,"False Data") -> USA | R13: =_xlfn.XLOOKUP(Table17[[#This Row],[Customer_ID]],Customer_Dim!A:A,Customer_Dim!H:H,"False Data") -> Bronze | S13: =_xlfn.XLOOKUP(Table17[[#This Row],[Store_ID]],Store_Dim!A:A,Store_Dim!B:B) -> Martinez, Adkins and Johnson | T13: =_xlfn.XLOOKUP(Table17[[#This Row],[Store_ID]],Store_Dim!A:A,Store_Dim!C:C) -> North | U13: =_xlfn.XLOOKUP(Table17[[#This Row],[Store_ID]],Store_Dim!A:A,Store_Dim!D:D) -> Danielmouth | V13: =_xlfn.XLOOKUP(Table17[[#This Row],[Store_ID]],Store_Dim!A:A,Store_Dim!E:E) -> Flagship | W13: =_xlfn.XLOOKUP(Table17[[#This Row],[Product_ID]],Product_Dim!A:A,Product_Dim!B:B) -> Portable Power Bank | X13: =_xlfn.XLOOKUP(Table17[[#This Row],[Product_ID]],Product_Dim!A:A,Product_Dim!C:C) -> Electronics | Y13: =_xlfn.XLOOKUP(Table17[[#This Row],[Product_ID]],Product_Dim!A:A,Product_Dim!D:D) -> Mobile | Z13: =_xlfn.XLOOKUP(Table17[[#This Row],[Product_ID]],Product_Dim!A:A,Product_Dim!E:E) -> Cummings and Sons | AA13: =_xlfn.XLOOKUP(Table17[[#This Row],[Product_ID]],Product_Dim!A:A,Product_Dim!F:F) -> 326.06 | AB13: =_xlfn.XLOOKUP(Table17[[#This Row],[Product_ID]],Product_Dim!A:A,Product_Dim!G:G) -> 301
... A27: SALE25 | B27: 45552 | C27: CUST1381 | D27: PROD5 | E27: STORE3 | F27: 4 | G27: 852.71 | H27: 0.14 | I27: PayPal | J27: 2933.3224 | K27: =_xlfn.XLOOKUP(Table17[[#This Row],[Customer_ID]],Customer_Dim!A:A,Customer_Dim!B:B,"False Data") -> Erika Padilla | L27: =_xlfn.XLOOKUP(Table17[[#This Row],[Customer_ID]],Customer_Dim!A:A,Customer_Dim!C:C,"False Data") -> 50 | M27: {=_xlfn.IFS(Table9[[#This Row],[Age]]<=35,"Youth",Table9[[#This Row],[Age]]<=55,"Adult",Table9[[#This Row],[Age]]>55,"Senior")} -> Adult | N27: =_xlfn.XLOOKUP(Table17[[#This Row],[Customer_ID]],Customer_Dim!A:A,Customer_Dim!D:D,"False Data") -> Male | O27: =_xlfn.XLOOKUP(Table17[[#This Row],[Customer_ID]],Customer_Dim!A:A,Customer_Dim!E:E,"False Data") -> Andrewsland | P27: =_xlfn.XLOOKUP(Table17[[#This Row],[Customer_ID]],Customer_Dim!A:A,Customer_Dim!F:F,"False Data") -> Alabama | Q27: =_xlfn.XLOOKUP(Table17[[#This Row],[Customer_ID]],Customer_Dim!A:A,Customer_Dim!G:G,"False Data") -> USA | R27: =_xlfn.XLOOKUP(Table17[[#This Row],[Customer_ID]],Customer_Dim!A:A,Customer_Dim!H:H,"False Data") -> Silver | S27: =_xlfn.XLOOKUP(Table17[[#This Row],[Store_ID]],Store_Dim!A:A,Store_Dim!B:B) -> Johnson-Wright | T27: =_xlfn.XLOOKUP(Table17[[#This Row],[Store_ID]],Store_Dim!A:A,Store_Dim!C:C) -> North | U27: =_xlfn.XLOOKUP(Table17[[#This Row],[Store_ID]],Store_Dim!A:A,Store_Dim!D:D) -> Hoodberg | V27: =_xlfn.XLOOKUP(Table17[[#This Row],[Store_ID]],Store_Dim!A:A,Store_Dim!E:E) -> Outlet | W27: =_xlfn.XLOOKUP(Table17[[#This Row],[Product_ID]],Product_Dim!A:A,Product_Dim!B:B) -> Men's Leather Belt | X27: =_xlfn.XLOOKUP(Table17[[#This Row],[Product_ID]],Product_Dim!A:A,Product_Dim!C:C) -> Clothing | Y27: =_xlfn.XLOOKUP(Table17[[#This Row],[Product_ID]],Product_Dim!A:A,Product_Dim!D:D) -> Accessories | Z27: =_xlfn.XLOOKUP(Table17[[#This Row],[Product_ID]],Product_Dim!A:A,Product_Dim!E:E) -> Baldwin, Garza and Gonzalez | AA27: =_xlfn.XLOOKUP(Table17[[#This Row],[Product_ID]],Product_Dim!A:A,Product_Dim!F:F) -> 261 | AB27: =_xlfn.XLOOKUP(Table17[[#This Row],[Product_ID]],Product_Dim!A:A,Product_Dim!G:G) -> 59
A28: SALE26 | B28: 45294 | C28: CUST1213 | D28: PROD98 | E28: STORE8 | F28: 4 | G28: 156.16 | H28: =1-(Table17[[#This Row],[Total_Amount]]/(Table17[[#This Row],[Unit_Price]]*Table17[[#This Row],[Quantity]])) -> 0.04 | I28: Credit Card | J28: 599.6544 | K28: =_xlfn.XLOOKUP(Table17[[#This Row],[Customer_ID]],Customer_Dim!A:A,Customer_Dim!B:B,"False Data") -> Stuart Johnson | L28: =_xlfn.XLOOKUP(Table17[[#This Row],[Customer_ID]],Customer_Dim!A:A,Customer_Dim!C:C,"False Data") -> 42 | M28: {=_xlfn.IFS(Table9[[#This Row],[Age]]<=35,"Youth",Table9[[#This Row],[Age]]<=55,"Adult",Table9[[#This Row],[Age]]>55,"Senior")} -> Adult | N28: =_xlfn.XLOOKUP(Table17[[#This Row],[Customer_ID]],Customer_Dim!A:A,Customer_Dim!D:D,"False Data") -> Female | O28: =_xlfn.XLOOKUP(Table17[[#This Row],[Customer_ID]],Customer_Dim!A:A,Customer_Dim!E:E,"False Data") -> West Markport | P28: =_xlfn.XLOOKUP(Table17[[#This Row],[Customer_ID]],Customer_Dim!A:A,Customer_Dim!F:F,"False Data") -> North Dakota | Q28: =_xlfn.XLOOKUP(Table17[[#This Row],[Customer_ID]],Customer_Dim!A:A,Customer_Dim!G:G,"False Data") -> USA | R28: =_xlfn.XLOOKUP(Table17[[#This Row],[Customer_ID]],Customer_Dim!A:A,Customer_Dim!H:H,"False Data") -> Platinum | S28: =_xlfn.XLOOKUP(Table17[[#This Row],[Store_ID]],Store_Dim!A:A,Store_Dim!B:B) -> Bean, Jones and Park | T28: =_xlfn.XLOOKUP(Table17[[#This Row],[Store_ID]],Store_Dim!A:A,Store_Dim!C:C) -> West | U28: =_xlfn.XLOOKUP(Table17[[#This Row],[Store_ID]],Store_Dim!A:A,Store_Dim!D:D) -> Thompsonborough | V28: =_xlfn.XLOOKUP(Table17[[#This Row],[Store_ID]],Store_Dim!A:A,Store_Dim!E:E) -> Online | W28: =_xlfn.XLOOKUP(Table17[[#This Row],[Product_ID]],Product_Dim!A:A,Product_Dim!B:B) -> Portable Bluetooth Speaker | X28: =_xlfn.XLOOKUP(Table17[[#This Row],[Product_ID]],Product_Dim!A:A,Product_Dim!C:C) -> Electronics | Y28: =_xlfn.XLOOKUP(Table17[[#This Row],[Product_ID]],Product_Dim!A:A,Product_Dim!D:D) -> Audio | Z28: =_xlfn.XLOOKUP(Table17[[#This Row],[Product_ID]],Product_Dim!A:A,Product_Dim!E:E) -> Flores-King | AA28: =_xlfn.XLOOKUP(Table17[[#This Row],[Product_ID]],Product_Dim!A:A,Product_Dim!F:F) -> 431.67 | AB28: =_xlfn.XLOOKUP(Table17[[#This Row],[Product_ID]],Product_Dim!A:A,Product_Dim!G:G) -> 73
A29: SALE27 | B29: 45710 | C29: CUST1200 | D29: PROD77 | E29: STORE8 | F29: 3 | G29: 815.49 | H29: 0.17 | I29: Credit Card | J29: 2030.5701 | K29: =_xlfn.XLOOKUP(Table17[[#This Row],[Customer_ID]],Customer_Dim!A:A,Customer_Dim!B:B,"False Data") -> Anna Perez | L29: =_xlfn.XLOOKUP(Table17[[#This Row],[Customer_ID]],Customer_Dim!A:A,Customer_Dim!C:C,"False Data") -> 30 | M29: {=_xlfn.IFS(Table9[[#This Row],[Age]]<=35,"Youth",Table9[[#This Row],[Age]]<=55,"Adult",Table9[[#This Row],[Age]]>55,"Senior")} -> Youth | N29: =_xlfn.XLOOKUP(Table17[[#This Row],[Customer_ID]],Customer_Dim!A:A,Customer_Dim!D:D,"False Data") -> Male | O29: =_xlfn.XLOOKUP(Table17[[#This Row],[Customer_ID]],Customer_Dim!A:A,Customer_Dim!E:E,"False Data") -> South Jerry | P29: =_xlfn.XLOOKUP(Table17[[#This Row],[Customer_ID]],Customer_Dim!A:A,Customer_Dim!F:F,"False Data") -> Maine | Q29: =_xlfn.XLOOKUP(Table17[[#This Row],[Customer_ID]],Customer_Dim!A:A,Customer_Dim!G:G,"False Data") -> USA | R29: =_xlfn.XLOOKUP(Table17[[#This Row],[Customer_ID]],Customer_Dim!A:A,Customer_Dim!H:H,"False Data") -> Platinum | S29: =_xlfn.XLOOKUP(Table17[[#This Row],[Store_ID]],Store_Dim!A:A,Store_Dim!B:B) -> Bean, Jones and Park | T29: =_xlfn.XLOOKUP(Table17[[#This Row],[Store_ID]],Store_Dim!A:A,Store_Dim!C:C) -> West | U29: =_xlfn.XLOOKUP(Table17[[#This Row],[Store_ID]],Store_Dim!A:A,Store_Dim!D:D) -> Thompsonborough | V29: =_xlfn.XLOOKUP(Table17[[#This Row],[Store_ID]],Store_Dim!A:A,Store_Dim!E:E) -> Online | W29: =_xlfn.XLOOKUP(Table17[[#This Row],[Product_ID]],Product_Dim!A:A,Product_Dim!B:B) -> WiFi Mesh Router | X29: =_xlfn.XLOOKUP(Table17[[#This Row],[Product_ID]],Product_Dim!A:A,Product_Dim!C:C) -> Electronics | Y29: =_xlfn.XLOOKUP(Table17[[#This Row],[Product_ID]],Product_Dim!A:A,Product_Dim!D:D) -> Appliances | Z29: =_xlfn.XLOOKUP(Table17[[#This Row],[Product_ID]],Product_Dim!A:A,Product_Dim!E:E) -> White, Reeves and Woods | AA29: =_xlfn.XLOOKUP(Table17[[#This Row],[Product_ID]],Product_Dim!A:A,Product_Dim!F:F) -> 480.9 | AB29: =_xlfn.XLOOKUP(Table17[[#This Row],[Product_ID]],Product_Dim!A:A,Product_Dim!G:G) -> 104
A30: SALE28 | B30: 45923 | C30: CUST1148 | D30: PROD13 | E30: STORE2 | F30: 2 | G30: 74.21 | H30: 0.11 | I30: PayPal | J30: 132.0938 | K30: =_xlfn.XLOOKUP(Table17[[#This Row],[Customer_ID]],Customer_Dim!A:A,Customer_Dim!B:B,"False Data") -> Theresa Campbell | L30: =_xlfn.XLOOKUP(Table17[[#This Row],[Customer_ID]],Customer_Dim!A:A,Customer_Dim!C:C,"False Data") -> 42 | M30: {=_xlfn.IFS(Table9[[#This Row],[Age]]<=35,"Youth",Table9[[#This Row],[Age]]<=55,"Adult",Table9[[#This Row],[Age]]>55,"Senior")} -> Adult | N30: =_xlfn.XLOOKUP(Table17[[#This Row],[Customer_ID]],Customer_Dim!A:A,Customer_Dim!D:D,"False Data") -> Female | O30: =_xlfn.XLOOKUP(Table17[[#This Row],[Customer_ID]],Customer_Dim!A:A,Customer_Dim!E:E,"False Data") -> New Brian | P30: =_xlfn.XLOOKUP(Table17[[#This Row],[Customer_ID]],Customer_Dim!A:A,Customer_Dim!F:F,"False Data") -> Wisconsin | Q30: =_xlfn.XLOOKUP(Table17[[#This Row],[Customer_ID]],Customer_Dim!A:A,Customer_Dim!G:G,"False Data") -> USA | R30: =_xlfn.XLOOKUP(Table17[[#This Row],[Customer_ID]],Customer_Dim!A:A,Customer_Dim!H:H,"False Data") -> Bronze | S30: =_xlfn.XLOOKUP(Table17[[#This Row],[Store_ID]],Store_Dim!A:A,Store_Dim!B:B) -> Black-Horn | T30: =_xlfn.XLOOKUP(Table17[[#This Row],[Store_ID]],Store_Dim!A:A,Store_Dim!C:C) -> South | U30: =_xlfn.XLOOKUP(Table17[[#This Row],[Store_ID]],Store_Dim!A:A,Store_Dim!D:D) -> North Nancyview | V30: =_xlfn.XLOOKUP(Table17[[#This Row],[Store_ID]],Store_Dim!A:A,Store_Dim!E:E) -> Outlet | W30: =_xlfn.XLOOKUP(Table17[[#This Row],[Product_ID]],Product_Dim!A:A,Product_Dim!B:B) -> USB-C Fast Charger | X30: =_xlfn.XLOOKUP(Table17[[#This Row],[Product_ID]],Product_Dim!A:A,Product_Dim!C:C) -> Electronics | Y30: =_xlfn.XLOOKUP(Table17[[#This Row],[Product_ID]],Product_Dim!A:A,Product_Dim!D:D) -> Accessories | Z30: =_xlfn.XLOOKUP(Table17[[#This Row],[Product_ID]],Product_Dim!A:A,Product_Dim!E:E) -> Dawson-Perkins | AA30: =_xlfn.XLOOKUP(Table17[[#This Row],[Product_ID]],Product_Dim!A:A,Product_Dim!F:F) -> 242.23 | AB30: =_xlfn.XLOOKUP(Table17[[#This Row],[Product_ID]],Product_Dim!A:A,Product_Dim!G:G) -> 453
A31: SALE29 | B31: 45302 | C31: CUST1348 | D31: PROD99 | E31: STORE3 | F31: 4 | G31: 451.67 | H31: 0.15 | I31: Credit Card | J31: 1535.678 | K31: =_xlfn.XLOOKUP(Table17[[#This Row],[Customer_ID]],Customer_Dim!A:A,Customer_Dim!B:B,"False Data") -> Sherry Cabrera | L31: =_xlfn.XLOOKUP(Table17[[#This Row],[Customer_ID]],Customer_Dim!A:A,Customer_Dim!C:C,"False Data") -> 55 | M31: {=_xlfn.IFS(Table9[[#This Row],[Age]]<=35,"Youth",Table9[[#This Row],[Age]]<=55,"Adult",Table9[[#This Row],[Age]]>55,"Senior")} -> Adult | N31: =_xlfn.XLOOKUP(Table17[[#This Row],[Customer_ID]],Customer_Dim!A:A,Customer_Dim!D:D,"False Data") -> Male | O31: =_xlfn.XLOOKUP(Table17[[#This Row],[Customer_ID]],Customer_Dim!A:A,Customer_Dim!E:E,"False Data") -> Shannonview | P31: =_xlfn.XLOOKUP(Table17[[#This Row],[Customer_ID]],Customer_Dim!A:A,Customer_Dim!F:F,"False Data") -> Pennsylvania | Q31: =_xlfn.XLOOKUP(Table17[[#This Row],[Customer_ID]],Customer_Dim!A:A,Customer_Dim!G:G,"False Data") -> USA | R31: =_xlfn.XLOOKUP(Table17[[#This Row],[Customer_ID]],Customer_Dim!A:A,Customer_Dim!H:H,"False Data") -> Silver | S31: =_xlfn.XLOOKUP(Table17[[#This Row],[Store_ID]],Store_Dim!A:A,Store_Dim!B:B) -> Johnson-Wright | T31: =_xlfn.XLOOKUP(Table17[[#This Row],[Store_ID]],Store_Dim!A:A,Store_Dim!C:C) -> North | U31: =_xlfn.XLOOKUP(Table17[[#This Row],[Store_ID]],Store_Dim!A:A,Store_Dim!D:D) -> Hoodberg | V31: =_xlfn.XLOOKUP(Table17[[#This Row],[Store_ID]],Store_Dim!A:A,Store_Dim!E:E) -> Outlet | W31: =_xlfn.XLOOKUP(Table17[[#This Row],[Product_ID]],Product_Dim!A:A,Product_Dim!B:B) -> Stainless Steel Cookware Set | X31: =_xlfn.XLOOKUP(Table17[[#This Row],[Product_ID]],Product_Dim!A:A,Product_Dim!C:C) -> Home | Y31: =_xlfn.XLOOKUP(Table17[[#This Row],[Product_ID]],Product_Dim!A:A,Product_Dim!D:D) -> Kitchen | Z31: =_xlfn.XLOOKUP(Table17[[#This Row],[Product_ID]],Product_Dim!A:A,Product_Dim!E:E) -> Campbell Ltd | AA31: =_xlfn.XLOOKUP(Table17[[#This Row],[Product_ID]],Product_Dim!A:A,Product_Dim!F:F) -> 201.41 | AB31: =_xlfn.XLOOKUP(Table17[[#This Row],[Product_ID]],Product_Dim!A:A,Product_Dim!G:G) -> 146
A32: SALE30 | B32: 45217 | C32: CUST1028 | D32: PROD5 | E32: STORE19 | F32: 1 | G32: 429.38 | H32: 0.13 | I32: PayPal | J32: 373.5606 | K32: =_xlfn.XLOOKUP(Table17[[#This Row],[Customer_ID]],Customer_Dim!A:A,Customer_Dim!B:B,"False Data") -> Joshua Ryan | L32: =_xlfn.XLOOKUP(Table17[[#This Row],[Customer_ID]],Customer_Dim!A:A,Customer_Dim!C:C,"False Data") -> 27 | M32: {=_xlfn.IFS(Table9[[#This Row],[Age]]<=35,"Youth",Table9[[#This Row],[Age]]<=55,"Adult",Table9[[#This Row],[Age]]>55,"Senior")} -> Youth | N32: =_xlfn.XLOOKUP(Table17[[#This Row],[Customer_ID]],Customer_Dim!A:A,Customer_Dim!D:D,"False Data") -> Female | O32: =_xlfn.XLOOKUP(Table17[[#This Row],[Customer_ID]],Customer_Dim!A:A,Customer_Dim!E:E,"False Data") -> New David | P32: =_xlfn.XLOOKUP(Table17[[#This Row],[Customer_ID]],Customer_Dim!A:A,Customer_Dim!F:F,"False Data") -> New Jersey | Q32: =_xlfn.XLOOKUP(Table17[[#This Row],[Customer_ID]],Customer_Dim!A:A,Customer_Dim!G:G,"False Data") -> USA | R32: =_xlfn.XLOOKUP(Table17[[#This Row],[Customer_ID]],Customer_Dim!A:A,Customer_Dim!H:H,"False Data") -> Platinum | S32: =_xlfn.XLOOKUP(Table17[[#This Row],[Store_ID]],Store_Dim!A:A,Store_Dim!B:B) -> Mann-Austin | T32: =_xlfn.XLOOKUP(Table17[[#This Row],[Store_ID]],Store_Dim!A:A,Store_Dim!C:C) -> East | U32: =_xlfn.XLOOKUP(Table17[[#This Row],[Store_ID]],Store_Dim!A:A,Store_Dim!D:D) -> Vasquezborough | V32: =_xlfn.XLOOKUP(Table17[[#This Row],[Store_ID]],Store_Dim!A:A,Store_Dim!E:E) -> Online | W32: =_xlfn.XLOOKUP(Table17[[#This Row],[Product_ID]],Product_Dim!A:A,Product_Dim!B:B) -> Men's Leather Belt | X32: =_xlfn.XLOOKUP(Table17[[#This Row],[Product_ID]],Product_Dim!A:A,Product_Dim!C:C) -> Clothing | Y32: =_xlfn.XLOOKUP(Table17[[#This Row],[Product_ID]],Product_Dim!A:A,Product_Dim!D:D) -> Accessories | Z32: =_xlfn.XLOOKUP(Table17[[#This Row],[Product_ID]],Product_Dim!A:A,Product_Dim!E:E) -> Baldwin, Garza and Gonzalez | AA32: =_xlfn.XLOOKUP(Table17[[#This Row],[Product_ID]],Product_Dim!A:A,Product_Dim!F:F) -> 261 | AB32: =_xlfn.XLOOKUP(Table17[[#This Row],[Product_ID]],Product_Dim!A:A,Product_Dim!G:G) -> 59
